#VRML_SIM R2023b utf8

EXTERNPROTO "https://raw.githubusercontent.com/cyberbotics/webots/R2023b/projects/objects/backgrounds/protos/TexturedBackground.proto"
EXTERNPROTO "https://raw.githubusercontent.com/cyberbotics/webots/R2023b/projects/objects/backgrounds/protos/TexturedBackgroundLight.proto"
EXTERNPROTO "https://raw.githubusercontent.com/cyberbotics/webots/R2023b/projects/objects/floors/protos/Floor.proto"
IMPORTABLE EXTERNPROTO "https://raw.githubusercontent.com/cyberbotics/webots/R2023b/projects/humans/pedestrian/protos/Pedestrian.proto"
EXTERNPROTO "https://raw.githubusercontent.com/cyberbotics/webots/R2023b/projects/appearances/protos/MattePaint.proto"
EXTERNPROTO "https://raw.githubusercontent.com/cyberbotics/webots/R2023b/projects/objects/street_furniture/protos/Atm.proto"
EXTERNPROTO "https://raw.githubusercontent.com/cyberbotics/webots/R2023b/projects/objects/street_furniture/protos/FireHydrant.proto"
EXTERNPROTO "https://raw.githubusercontent.com/cyberbotics/webots/R2023b/projects/objects/street_furniture/protos/Bench.proto"
EXTERNPROTO "https://raw.githubusercontent.com/cyberbotics/webots/R2023b/projects/objects/street_furniture/protos/TrashBin.proto"

WorldInfo {
  contactProperties [
    ContactProperties {
      material1 "InteriorWheelMat"
      coulombFriction [
        0, 2, 0
      ]
      frictionRotation -0.785398 0
      bounce 0
      forceDependentSlip [
        10, 0
      ]
      softCFM 0.0001
    }
    ContactProperties {
      material1 "ExteriorWheelMat"
      coulombFriction [
        0, 2, 0
      ]
      frictionRotation 0.785398 0
      bounce 0
      forceDependentSlip [
        10, 0
      ]
      softCFM 0.0001
    }
  ]
}
Viewpoint {
  orientation -0.13466066694289572 0.5766628554262906 -0.8058079522752873 0.37102888332405465
  position -11.98587033892705 2.6886871133367345 3.273872551579492
}
TexturedBackground {
}
TexturedBackgroundLight {
}
Floor {
}
DEF USER Pedestrian {
  translation 0.76067 -0.850336 1.27
  name "user"
  controller "<none>"
  enableBoundingObject TRUE
}
Solid {
  translation 0.67 0 0.09342572594794567
  children [
    Shape {
      appearance PBRAppearance {
      }
      geometry DEF BALL_GEOMETRY Sphere {
        radius 0.1
      }
    }
  ]
  boundingObject USE BALL_GEOMETRY
  physics Physics {
  }
  linearVelocity 0 0 -3.681158500848673e-06
}
DEF DOG Robot {
  translation -6.351291862243846 -0.07052626902822112 0.267871416195447
  rotation -0.000589583648295652 -0.004168096509033302 -0.9999911396420536 0.49992085457418534
  children [
    DEF ROBOT_BASE Solid {
      translation 3.5 0.39 -0.00169354
      children [
        InertialUnit {
          name "imu"
        }
        Solid {
          translation 0.28 0 -0.00999987
          rotation 0 1 0 -1.5707953071795862
          children [
            Lidar {
              translation 5.87712e-07 0 -0.05
              rotation 0 1 0 1.5708
              name "front_lidar"
            }
            Shape {
              appearance MattePaint {
                baseColor 1 1 0
              }
              geometry Capsule {
                height 0.05
                radius 0.025
              }
            }
          ]
          name "Front_Lidar_Solid"
        }
        Solid {
          translation 0.29 0 0.08
          rotation 0 1 0 -1.5707953071795862
          children [
            Shape {
              appearance MattePaint {
                baseColor 0 1 1
              }
              geometry Cylinder {
                height 0.05
                radius 0.02
              }
            }
            Camera {
              translation 0 0 -0.025
              rotation 0 1 0 1.5708
              name "front_camera"
              fieldOfView 1.52
              width 640
              height 480
              recognition Recognition {
                maxRange 20
                frameThickness 3
                segmentation TRUE
              }
            }
          ]
          name "Front_Camera_Solid"
        }
        Solid {
          translation 0 0 0.15
          children [
            Speaker {
            }
            Shape {
              appearance MattePaint {
                baseColor 0 0.333333 0
              }
              geometry Box {
                size 0.05 0.05 0.05
              }
            }
            GPS {
            }
          ]
          name "GPS"
        }
        HingeJoint {
          jointParameters HingeJointParameters {
            position -111.75382218664942
            axis 0 1 0
            anchor 0.2 -0.2 -0.15
          }
          device [
            RotationalMotor {
              name "front_right_wheel"
            }
            PositionSensor {
            }
          ]
          endPoint Solid {
            translation 0.2 -0.19999999999999996 -0.1499999999999999
            rotation 0.6645406989081559 0.5283861179817915 -0.5283878971161168 1.9685370874843524
            children [
              DEF Wheel Shape {
                appearance MattePaint {
                  baseColor 0 0 0
                }
                geometry DEF Wheel_size Cylinder {
                  height 0.05
                  radius 0.125
                }
              }
            ]
            name "wheel_1"
            contactMaterial "InteriorWheelMat"
            boundingObject USE Wheel_size
            physics Physics {
            }
            linearVelocity 3.4621552636146395e-14 2.0484979416215438e-14 -6.022001552285058e-16
            angularVelocity 2.280754976617788e-13 4.125763863132574e-13 1.2465823924311776e-13
          }
        }
        HingeJoint {
          jointParameters HingeJointParameters {
            position 4.868619624213832
            axis 0 1 0
            anchor 0.2 0.2 -0.15
          }
          device [
            RotationalMotor {
              name "front_left_wheel"
            }
            PositionSensor {
            }
          ]
          endPoint Solid {
            translation 0.2 0.19999999999999996 -0.15000000000000005
            rotation -0.6373937128434148 0.5448519320325379 -0.5448537666090759 4.276513696430008
            children [
              USE Wheel
            ]
            name "wheel_2"
            contactMaterial "ExteriorWheelMat"
            boundingObject USE Wheel_size
            physics Physics {
            }
            linearVelocity -4.720336447134244e-15 4.529878202237573e-14 -4.180292327891502e-18
            angularVelocity -2.3475509866719095e-13 -4.2785077008941617e-13 1.2604588670535964e-13
          }
        }
        HingeJoint {
          jointParameters HingeJointParameters {
            position -68.25552450076422
            axis 0 1 0
            anchor -0.2 -0.2 -0.15
          }
          device [
            RotationalMotor {
              name "back_right_wheel"
            }
            PositionSensor {
            }
          ]
          endPoint Solid {
            translation -0.19999999999999996 -0.19999999999999996 -0.15000000000000002
            rotation -0.8391442389911078 -0.3846010595760833 0.38460235457026076 4.537905091934368
            children [
              USE Wheel
            ]
            name "wheel_3"
            contactMaterial "ExteriorWheelMat"
            boundingObject USE Wheel_size
            physics Physics {
            }
            linearVelocity 1.878754528942712e-14 -2.4300093971232474e-14 -7.870355087261203e-16
            angularVelocity 1.4757272145238349e-13 2.677353616496361e-13 1.2535477243940662e-13
          }
        }
        HingeJoint {
          jointParameters HingeJointParameters {
            position -20.172713371720043
            axis 0 1 0
            anchor -0.2 0.2 -0.15
          }
          device [
            RotationalMotor {
              name "back_left_wheel"
            }
            PositionSensor {
            }
          ]
          endPoint Solid {
            translation -0.2 0.19999999999999996 -0.14999999999999994
            rotation -0.672285175851617 0.5234648016089157 -0.5234665641726308 4.325354056731807
            children [
              USE Wheel
            ]
            name "wheel_4"
            contactMaterial "InteriorWheelMat"
            boundingObject USE Wheel_size
            physics Physics {
            }
            linearVelocity -3.425027170656649e-14 -8.001530034741481e-16 -6.927655217854626e-16
            angularVelocity -1.8558349131580678e-13 -3.516310460121396e-13 1.2535477647064816e-13
          }
        }
        HingeJoint {
          jointParameters HingeJointParameters {
            position -96.4556062499997
            axis 0 0 1
            anchor -0.12 0 0.2
          }
          device [
            PositionSensor {
            }
            RotationalMotor {
              name "gimbal_j1_motor"
            }
          ]
          endPoint Solid {
            translation -0.12 0 0.2
            rotation -2.3463533268661704e-06 -1.182681301825694e-06 0.9999999999965479 4.075358664870905
            children [
              HingeJoint {
                jointParameters HingeJointParameters {
                  position -0.8462499999999997
                  axis 0 1 0
                  anchor 0 0 0.08
                  minStop -0.52
                  maxStop 0.52
                }
                device [
                  RotationalMotor {
                    name "gimbal_j2_motor"
                  }
                  PositionSensor {
                  }
                ]
                endPoint Solid {
                  translation 0 0 0.08
                  rotation 0.8434733407723147 -0.3798365855819146 0.37983798080216163 1.7402107187731326
                  children [
                    Solid {
                      rotation 1 0 0 -1.5707953071795862
                      children [
                        Camera {
                          translation -0.036 0 0
                          rotation 0 0 1 3.141592653589793
                          name "RGB_camera"
                          recognitionColors [
                            0 0 0
                          ]
                          fieldOfView 1.518
                          width 640
                          height 480
                          noise 0.01
                          recognition Recognition {
                            segmentation TRUE
                          }
                        }
                        RangeFinder {
                          translation -0.035 0 0
                          rotation 0 0 1 3.141592653589793
                          name "range_finder"
                          fieldOfView 1.52
                          width 640
                          height 480
                          minRange 0.06
                          maxRange 6
                          noise 0.05
                        }
                        Shape {
                          appearance MattePaint {
                            baseColor 0 0 0
                          }
                          geometry Box {
                            size 0.07 0.18 0.04
                          }
                        }
                      ]
                      name "Depth_Camera"
                    }
                    Shape {
                      appearance MattePaint {
                        baseColor 0 0.666667 1
                      }
                      geometry Cylinder {
                        height 0.2
                        radius 0.03
                      }
                    }
                  ]
                  name "Gimbal_Joint_2"
                }
              }
              Shape {
                appearance MattePaint {
                  baseColor 0.333333 1 1
                }
                geometry Cylinder {
                  height 0.1
                  radius 0.04
                }
              }
            ]
            name "Gimbal_Joint_1"
          }
        }
        Shape {
          appearance MattePaint {
            baseColor 0.333333 0 1
          }
          geometry DEF BASE Box {
            size 0.6 0.3 0.3
          }
        }
      ]
      name "Gimbal"
      boundingObject USE BASE
      physics Physics {
      }
    }
  ]
  physics Physics {
  }
  controller "<extern>"
  supervisor TRUE
  linearVelocity 6.755016747981492e-15 3.1157702680543894e-15 -6.614506921984933e-17
  angularVelocity -6.433937781016568e-16 4.6483103637276955e-17 1.2473590395565772e-13
}
Robot {
  translation 0.1 0 0.1
  name "supervisor1"
  controller "supervisor_controller"
  supervisor TRUE
}
Robot {
  children [
    Solid {
      children [
        Emitter {
        }
        Receiver {
        }
        Shape {
          appearance MattePaint {
            baseColor 0 1 0
          }
          geometry Cone {
            bottomRadius 0.09
            height 0.3
          }
        }
      ]
    }
  ]
  name "remote_server"
}
Atm {
  translation 3.1 0 0
  rotation 0 0 1 -2.8797953071795863
}
TrashBin {
  translation 0 1.61 0
}
FireHydrant {
  translation 1.75 2.43 0
}
Bench {
  translation 0 -3.34 0
  rotation 2.3464099999897377e-06 1.8004599999921255e-06 0.9999999999956264 1.8326
}
