#VRML_SIM R2023b utf8

EXTERNPROTO "https://raw.githubusercontent.com/cyberbotics/webots/R2023b/projects/objects/backgrounds/protos/TexturedBackground.proto"
EXTERNPROTO "https://raw.githubusercontent.com/cyberbotics/webots/R2023b/projects/objects/backgrounds/protos/TexturedBackgroundLight.proto"
EXTERNPROTO "https://raw.githubusercontent.com/cyberbotics/webots/R2023b/projects/objects/floors/protos/Floor.proto"
IMPORTABLE EXTERNPROTO "https://raw.githubusercontent.com/cyberbotics/webots/R2023b/projects/humans/pedestrian/protos/Pedestrian.proto"
EXTERNPROTO "https://raw.githubusercontent.com/cyberbotics/webots/R2023b/projects/appearances/protos/MattePaint.proto"

WorldInfo {
  gpsCoordinateSystem "WGS84"
  contactProperties [
    ContactProperties {
      material1 "InteriorWheelMat"
      coulombFriction [
        0, 2, 0
      ]
      frictionRotation -0.785398 0
      bounce 0
      forceDependentSlip [
        10, 0
      ]
      softCFM 0.0001
    }
    ContactProperties {
      material1 "ExteriorWheelMat"
      coulombFriction [
        0, 2, 0
      ]
      frictionRotation 0.785398 0
      bounce 0
      forceDependentSlip [
        10, 0
      ]
      softCFM 0.0001
    }
  ]
}
Viewpoint {
  orientation 0.18394440911166982 0.30062557831984826 -0.9358358381769826 1.3148870198354135
  position -4.38831841291179 11.260235128298895 5.020408431637702
}
TexturedBackground {
}
TexturedBackgroundLight {
}
Floor {
}
DEF USER Pedestrian {
  translation 0.76067 -0.850336 1.27
  name "user"
  controller "<none>"
  enableBoundingObject TRUE
}
Solid {
  translation 0.67 0 0.0934252748951154
  children [
    Shape {
      appearance PBRAppearance {
      }
      geometry DEF BALL_GEOMETRY Sphere {
        radius 0.1
      }
    }
  ]
  boundingObject USE BALL_GEOMETRY
  physics Physics {
  }
}
DEF DOG Robot {
  translation -1.06664 1.04566 0.25
  children [
    DEF ROBOT_BASE Solid {
      translation 0 0 -0.0016935350243008074
      children [
        Solid {
          translation 0.24 0 0.17
          children [
            Speaker {
            }
            Shape {
              appearance Appearance {
              }
              geometry Box {
                size 0.05 0.05 0.05
              }
            }
          ]
          name "speaker"
        }
        Solid {
          translation 0.28 0 -0.00999987
          rotation 0 1 0 -1.5707953071795862
          children [
            Lidar {
              translation 5.87712e-07 0 -0.05
              rotation 0 1 0 1.5708
              name "front_lidar"
            }
            Shape {
              appearance MattePaint {
                baseColor 1 1 0
              }
              geometry Capsule {
                height 0.05
                radius 0.025
              }
            }
          ]
          name "Front_Lidar_Solid"
        }
        Solid {
          translation 0.29 0 0.08
          rotation 0 1 0 -1.5707953071795862
          children [
            Shape {
              appearance MattePaint {
                baseColor 0 1 1
              }
              geometry Cylinder {
                height 0.05
                radius 0.02
              }
            }
            Camera {
              translation 0 0 -0.025
              rotation 0 1 0 1.5708
              name "front_camera"
            }
          ]
          name "Front_Camera_Solid"
        }
        Solid {
          translation 0 0 0.15
          children [
            Shape {
              appearance MattePaint {
                baseColor 0 0.333333 0
              }
              geometry Box {
                size 0.05 0.05 0.05
              }
            }
            GPS {
            }
          ]
          name "GPS"
        }
        HingeJoint {
          jointParameters HingeJointParameters {
            axis 0 1 0
            anchor 0.2 -0.2 -0.15
          }
          device [
            RotationalMotor {
            }
            PositionSensor {
            }
          ]
          endPoint Solid {
            translation 0.19999999999999993 -0.19999999999999996 -0.14999999999999997
            rotation 1 -9.467871502676632e-09 9.46790368535116e-09 1.5707996938994835
            children [
              DEF Wheel Shape {
                appearance MattePaint {
                  baseColor 0 0 0
                }
                geometry DEF Wheel_size Cylinder {
                  height 0.05
                  radius 0.08
                }
              }
            ]
            name "wheel_1"
            contactMaterial "InteriorWheelMat"
            boundingObject USE Wheel_size
            physics Physics {
            }
          }
        }
        HingeJoint {
          jointParameters HingeJointParameters {
            axis 0 1 0
            anchor 0.2 0.2 -0.15
          }
          device [
            RotationalMotor {
            }
            PositionSensor {
            }
          ]
          endPoint Solid {
            translation 0.19999999999999993 0.19999999999999996 -0.14999999999999997
            rotation 1 9.447236440636552e-09 -9.447268416026151e-09 1.5707996938994848
            children [
              USE Wheel
            ]
            name "wheel_2"
            contactMaterial "ExteriorWheelMat"
            boundingObject USE Wheel_size
            physics Physics {
            }
          }
        }
        HingeJoint {
          jointParameters HingeJointParameters {
            axis 0 1 0
            anchor -0.2 -0.2 -0.15
          }
          device [
            RotationalMotor {
            }
            PositionSensor {
            }
          ]
          endPoint Solid {
            translation -0.19999999999999998 -0.19999999999999996 -0.15
            rotation 1 9.447218919359309e-09 -9.447250462273926e-09 1.5707996938994868
            children [
              USE Wheel
            ]
            name "wheel_3"
            contactMaterial "ExteriorWheelMat"
            boundingObject USE Wheel_size
            physics Physics {
            }
          }
        }
        HingeJoint {
          jointParameters HingeJointParameters {
            axis 0 1 0
            anchor -0.2 0.2 -0.15
          }
          device [
            RotationalMotor {
            }
            PositionSensor {
            }
          ]
          endPoint Solid {
            translation -0.19999999999999998 0.19999999999999996 -0.15
            rotation 1 -9.467888552351852e-09 9.467920926104535e-09 1.5707996938994941
            children [
              USE Wheel
            ]
            name "wheel_4"
            contactMaterial "InteriorWheelMat"
            boundingObject USE Wheel_size
            physics Physics {
            }
          }
        }
        HingeJoint {
          jointParameters HingeJointParameters {
            axis 0 0 1
            anchor -0.12 0 0.2
          }
          device [
            PositionSensor {
            }
            RotationalMotor {
              name "gimbal_j1_motor"
            }
          ]
          endPoint Solid {
            translation -0.12 0 0.2
            rotation 9.0249935671988e-17 0.9999999999999999 0 4.692706653739929e-06
            children [
              HingeJoint {
                jointParameters HingeJointParameters {
                  axis 0 1 0
                  anchor 0 0 0.08
                  minStop -0.52
                  maxStop 0.52
                }
                device [
                  RotationalMotor {
                    name "gimbal_j2_motor"
                  }
                  PositionSensor {
                  }
                ]
                endPoint Solid {
                  translation 0 0 0.08
                  rotation 1 0 0 1.5707999999999998
                  children [
                    Solid {
                      rotation 1 0 0 -1.5707953071795862
                      children [
                        Camera {
                          translation -0.036 0 0
                          rotation 0 0 1 3.141592653589793
                          name "RGB_camera"
                          recognitionColors [
                            0 0 0
                          ]
                          fieldOfView 1.518
                          width 640
                          height 480
                          noise 0.01
                          recognition Recognition {
                            segmentation TRUE
                          }
                        }
                        RangeFinder {
                          translation -0.035 0 0
                          rotation 0 0 1 3.141592653589793
                          name "range_finder"
                          fieldOfView 1.52
                          width 640
                          height 480
                          minRange 0.06
                          maxRange 6
                          noise 0.05
                        }
                        Shape {
                          appearance MattePaint {
                            baseColor 0 0 0
                          }
                          geometry Box {
                            size 0.07 0.18 0.04
                          }
                        }
                      ]
                      name "Depth_Camera"
                    }
                    Shape {
                      appearance MattePaint {
                        baseColor 0 0.666667 1
                      }
                      geometry Cylinder {
                        height 0.2
                        radius 0.03
                      }
                    }
                  ]
                  name "Gimbal_Joint_2"
                }
              }
              Shape {
                appearance MattePaint {
                  baseColor 0.333333 1 1
                }
                geometry Cylinder {
                  height 0.1
                  radius 0.04
                }
              }
            ]
            name "Gimbal_Joint_1"
          }
        }
        Shape {
          appearance MattePaint {
            baseColor 0.333333 0 1
          }
          geometry DEF BASE Box {
            size 0.6 0.3 0.3
          }
        }
      ]
      name "Gimbal"
      boundingObject USE BASE
      physics Physics {
      }
    }
  ]
  boundingObject Box {
    size 0.1 0.1 0.1
  }
  physics Physics {
  }
  controller "<extern>"
  supervisor TRUE
}
Robot {
  translation 0.1 0 0.1
  name "supervisor1"
  controller "supervisor_controller"
  supervisor TRUE
}
