#VRML_SIM R2023b utf8

EXTERNPROTO "https://raw.githubusercontent.com/cyberbotics/webots/R2023b/projects/objects/backgrounds/protos/TexturedBackground.proto"
EXTERNPROTO "https://raw.githubusercontent.com/cyberbotics/webots/R2023b/projects/objects/backgrounds/protos/TexturedBackgroundLight.proto"
EXTERNPROTO "https://raw.githubusercontent.com/cyberbotics/webots/R2023b/projects/objects/floors/protos/Floor.proto"
IMPORTABLE EXTERNPROTO "https://raw.githubusercontent.com/cyberbotics/webots/R2023b/projects/humans/pedestrian/protos/Pedestrian.proto"
EXTERNPROTO "https://raw.githubusercontent.com/cyberbotics/webots/R2023b/projects/appearances/protos/MattePaint.proto"
EXTERNPROTO "https://raw.githubusercontent.com/cyberbotics/webots/R2023b/projects/objects/street_furniture/protos/Atm.proto"
EXTERNPROTO "https://raw.githubusercontent.com/cyberbotics/webots/R2023b/projects/objects/street_furniture/protos/FireHydrant.proto"
EXTERNPROTO "https://raw.githubusercontent.com/cyberbotics/webots/R2023b/projects/objects/street_furniture/protos/Bench.proto"
EXTERNPROTO "https://raw.githubusercontent.com/cyberbotics/webots/R2023b/projects/objects/street_furniture/protos/TrashBin.proto"
EXTERNPROTO "https://raw.githubusercontent.com/cyberbotics/webots/R2023b/projects/objects/street_furniture/protos/Mailbox.proto"

WorldInfo {
  contactProperties [
    ContactProperties {
      material1 "InteriorWheelMat"
      coulombFriction [
        0, 2, 0
      ]
      frictionRotation -0.785398 0
      bounce 0
      forceDependentSlip [
        10, 0
      ]
      softCFM 0.0001
    }
    ContactProperties {
      material1 "ExteriorWheelMat"
      coulombFriction [
        0, 2, 0
      ]
      frictionRotation 0.785398 0
      bounce 0
      forceDependentSlip [
        10, 0
      ]
      softCFM 0.0001
    }
  ]
}
Viewpoint {
  orientation 0.3306758670191869 0.6897962011016965 -0.6440766040749943 0.3883274203628082
  position -11.255422943502515 2.567309670817013 4.490720877388357
}
TexturedBackground {
}
TexturedBackgroundLight {
}
Floor {
}
DEF USER Pedestrian {
  translation -0.9953949526346313 -0.8983037250569373 1.27
  name "user"
  controller "<none>"
  enableBoundingObject TRUE
}
Solid {
  translation 2.83 -0.08 0.09342527489456726
  children [
    Shape {
      appearance PBRAppearance {
      }
      geometry DEF BALL_GEOMETRY Sphere {
        radius 0.1
      }
    }
  ]
  boundingObject USE BALL_GEOMETRY
  physics Physics {
  }
  linearVelocity 0 0 1.0856293312728803e-16
}
DEF DOG Robot {
  translation 0.9169881833852479 -0.2812732679453578 0.275205996124186
  rotation -1.5318650317306705e-07 2.0462032457281958e-08 -0.999999999999988 0.26561064470112206
  children [
    DEF ROBOT_BASE Solid {
      translation 0 0 -0.0016935350243008074
      children [
        InertialUnit {
          name "imu"
        }
        Solid {
          translation 0.28 0 -0.00999987
          rotation 0 1 0 -1.5707953071795862
          children [
            Lidar {
              translation 5.87712e-07 0 -0.05
              rotation 0 1 0 1.5708
              name "front_lidar"
            }
            Shape {
              appearance MattePaint {
                baseColor 1 1 0
              }
              geometry Capsule {
                height 0.05
                radius 0.025
              }
            }
          ]
          name "Front_Lidar_Solid"
        }
        Solid {
          translation 0.28 0 0.1
          rotation 0.7071072811865696 -3.3905013482585576e-09 0.7071062811861719 3.14159
          children [
            Shape {
              appearance MattePaint {
                baseColor 0 1 1
              }
              geometry Cylinder {
                height 0.05
                radius 0.02
              }
            }
            Camera {
              translation 2.12131e-07 9.4058e-08 0.025
              rotation -0.707108281185553 -3.3905013482517768e-09 -0.70710528118436 -3.1415853071795863
              name "front_camera"
              fieldOfView 1.52
              width 858
              height 480
              recognition Recognition {
                maxRange 20
                frameColor 0.109804 0.909804 1
                frameThickness 3
                segmentation TRUE
              }
            }
          ]
          name "Front_Camera_Solid"
        }
        Solid {
          translation 0 0 0.15
          children [
            Speaker {
            }
            Shape {
              appearance MattePaint {
                baseColor 0 0.333333 0
              }
              geometry Box {
                size 0.05 0.05 0.05
              }
            }
            GPS {
            }
          ]
          name "GPS"
        }
        HingeJoint {
          jointParameters HingeJointParameters {
            position -6.818021624027339
            axis 0 1 0
            anchor 0.2 -0.2 -0.15
          }
          device [
            RotationalMotor {
              name "front_right_wheel"
            }
            PositionSensor {
            }
          ]
          endPoint Solid {
            translation 0.19999999999999996 -0.19999999999999996 -0.15000000000000005
            rotation -0.9324520482639892 0.25547283433808504 -0.255473694543209 4.642505014125069
            children [
              DEF Wheel Shape {
                appearance MattePaint {
                  baseColor 0 0 0
                }
                geometry DEF Wheel_size Cylinder {
                  height 0.05
                  radius 0.125
                }
              }
            ]
            name "wheel_1"
            contactMaterial "InteriorWheelMat"
            boundingObject USE Wheel_size
            physics Physics {
            }
            linearVelocity -2.331158855009374e-16 -7.217805899425399e-17 6.498219198516024e-16
            angularVelocity -6.167403737577034e-15 -5.629796336667182e-16 5.226476985377068e-16
          }
        }
        HingeJoint {
          jointParameters HingeJointParameters {
            position 25.954720511069493
            axis 0 1 0
            anchor 0.2 0.2 -0.15
          }
          device [
            RotationalMotor {
              name "front_left_wheel"
            }
            PositionSensor {
            }
          ]
          endPoint Solid {
            translation 0.19999999999999998 0.19999999999999996 -0.14999999999999997
            rotation 0.8513008023352626 0.3710027068792555 -0.3710039560861896 1.7310984526615132
            children [
              USE Wheel
            ]
            name "wheel_2"
            contactMaterial "ExteriorWheelMat"
            boundingObject USE Wheel_size
            physics Physics {
            }
            linearVelocity -7.215791425560767e-16 1.4785844880854037e-16 6.82017751057029e-21
            angularVelocity -9.844274616977192e-16 3.9601556880565544e-15 5.127162928958826e-16
          }
        }
        HingeJoint {
          jointParameters HingeJointParameters {
            position 19.096270005310103
            axis 0 1 0
            anchor -0.2 -0.2 -0.15
          }
          device [
            RotationalMotor {
              name "back_right_wheel"
            }
            PositionSensor {
            }
          ]
          endPoint Solid {
            translation -0.19999999999999993 -0.19999999999999996 -0.15000000000000002
            rotation -0.984973011362505 -0.12212302496443525 0.12212343616609538 4.697245154332198
            children [
              USE Wheel
            ]
            name "wheel_3"
            contactMaterial "ExteriorWheelMat"
            boundingObject USE Wheel_size
            physics Physics {
            }
            linearVelocity 6.441173317635193e-16 -3.6376374494514477e-16 -8.343644621166923e-16
            angularVelocity 2.566787864933972e-15 1.994758831651163e-15 8.631041078815692e-16
          }
        }
        HingeJoint {
          jointParameters HingeJointParameters {
            position 0.046334459538971834
            axis 0 1 0
            anchor -0.2 0.2 -0.15
          }
          device [
            RotationalMotor {
              name "back_left_wheel"
            }
            PositionSensor {
            }
          ]
          endPoint Solid {
            translation -0.19999999999999998 0.19999999999999996 -0.15
            rotation 0.9994635212244839 0.02315886579437665 -0.02315894377284616 1.5713363166047807
            children [
              USE Wheel
            ]
            name "wheel_4"
            contactMaterial "InteriorWheelMat"
            boundingObject USE Wheel_size
            physics Physics {
            }
            linearVelocity 8.868278215014006e-16 4.177284465832232e-17 4.631027565443063e-16
            angularVelocity -4.522827747942631e-15 1.9657985327890004e-15 5.085976782980623e-16
          }
        }
        HingeJoint {
          jointParameters HingeJointParameters {
            position 10.034264375000017
            axis 0 0 1
            anchor -0.12 0 0.2
          }
          device [
            PositionSensor {
            }
            RotationalMotor {
              name "gimbal_j1_motor"
            }
          ]
          endPoint Solid {
            translation -0.12 0 0.2
            rotation 2.3463533268671733e-06 7.380243329474589e-07 -0.999999999996975 2.5321062393608873
            children [
              HingeJoint {
                jointParameters HingeJointParameters {
                  position -0.20302500000000007
                  axis 0 1 0
                  anchor 0 0 0.08
                  minStop -0.52
                  maxStop 0.52
                }
                device [
                  RotationalMotor {
                    name "gimbal_j2_motor"
                  }
                  PositionSensor {
                  }
                ]
                endPoint Solid {
                  translation 0 0 0.08
                  rotation 0.9897827902319422 -0.10082150932293185 0.10082187966169459 1.581069583021165
                  children [
                    Solid {
                      rotation -0.9999999999999999 0 0 1.5707953071795862
                      children [
                        Camera {
                          translation 0.034 0 0
                          name "RGB_camera"
                          recognitionColors [
                            0 0 0
                          ]
                          fieldOfView 1.518
                          width 640
                          height 480
                          noise 0.01
                          recognition Recognition {
                            segmentation TRUE
                          }
                        }
                        RangeFinder {
                          translation 0.034 0 0
                          name "range_finder"
                          fieldOfView 1.52
                          width 640
                          height 480
                          minRange 0.06
                          maxRange 6
                          noise 0.05
                        }
                        Shape {
                          appearance MattePaint {
                            baseColor 0 0 0
                          }
                          geometry Box {
                            size 0.07 0.18 0.04
                          }
                        }
                      ]
                      name "Depth_Camera"
                    }
                    Shape {
                      appearance MattePaint {
                        baseColor 0 0.666667 1
                      }
                      geometry Cylinder {
                        height 0.2
                        radius 0.03
                      }
                    }
                  ]
                  name "Gimbal_Joint_2"
                }
              }
              Shape {
                appearance MattePaint {
                  baseColor 0.333333 1 1
                }
                geometry Cylinder {
                  height 0.1
                  radius 0.04
                }
              }
            ]
            name "Gimbal_Joint_1"
          }
        }
        Shape {
          appearance MattePaint {
            baseColor 0.333333 0 1
          }
          geometry DEF BASE Box {
            size 0.6 0.3 0.3
          }
        }
      ]
      name "Gimbal"
      boundingObject USE BASE
      physics Physics {
      }
    }
  ]
  physics Physics {
  }
  controller "<extern>"
  supervisor TRUE
  linearVelocity 4.4238678983767837e-16 3.2079153196404337e-16 1.9843520765954798e-16
  angularVelocity -1.1241229605727732e-15 1.0066178806603343e-15 5.271211397128066e-16
}
Robot {
  translation 0.1 0 0.1
  name "supervisor1"
  controller "supervisor_controller_auto"
  supervisor TRUE
}
Robot {
  children [
    Solid {
      children [
        Emitter {
        }
        Receiver {
        }
        Shape {
          appearance MattePaint {
            baseColor 0 1 0
          }
          geometry Cone {
            bottomRadius 0.09
            height 0.3
          }
        }
      ]
    }
  ]
  name "remote_server"
}
Atm {
  translation 3 1 0
  rotation 0 0 1 -2.8797953071795863
}
TrashBin {
  translation 0 1.61 0
}
FireHydrant {
  translation 1.75 2.43 0
}
Bench {
  translation 0 -3.34 0
  rotation 2.3464099999897377e-06 1.8004599999921255e-06 0.9999999999956264 1.8326
}
Mailbox {
  translation 2.25 -2.26 0
  rotation 0 0 1 2.87979
}
