#VRML_SIM R2023b utf8

EXTERNPROTO "https://raw.githubusercontent.com/cyberbotics/webots/R2023b/projects/objects/backgrounds/protos/TexturedBackground.proto"
EXTERNPROTO "https://raw.githubusercontent.com/cyberbotics/webots/R2023b/projects/objects/backgrounds/protos/TexturedBackgroundLight.proto"
EXTERNPROTO "https://raw.githubusercontent.com/cyberbotics/webots/R2023b/projects/objects/floors/protos/Floor.proto"
IMPORTABLE EXTERNPROTO "https://raw.githubusercontent.com/cyberbotics/webots/R2023b/projects/humans/pedestrian/protos/Pedestrian.proto"
EXTERNPROTO "https://raw.githubusercontent.com/cyberbotics/webots/R2023b/projects/appearances/protos/MattePaint.proto"
EXTERNPROTO "https://raw.githubusercontent.com/cyberbotics/webots/R2023b/projects/objects/street_furniture/protos/Atm.proto"
EXTERNPROTO "https://raw.githubusercontent.com/cyberbotics/webots/R2023b/projects/objects/street_furniture/protos/FireHydrant.proto"
EXTERNPROTO "https://raw.githubusercontent.com/cyberbotics/webots/R2023b/projects/objects/street_furniture/protos/Bench.proto"
EXTERNPROTO "https://raw.githubusercontent.com/cyberbotics/webots/R2023b/projects/objects/street_furniture/protos/TrashBin.proto"
EXTERNPROTO "https://raw.githubusercontent.com/cyberbotics/webots/R2023b/projects/objects/street_furniture/protos/Mailbox.proto"

WorldInfo {
  contactProperties [
    ContactProperties {
      material1 "InteriorWheelMat"
      coulombFriction [
        0, 2, 0
      ]
      frictionRotation -0.785398 0
      bounce 0
      forceDependentSlip [
        10, 0
      ]
      softCFM 0.0001
    }
    ContactProperties {
      material1 "ExteriorWheelMat"
      coulombFriction [
        0, 2, 0
      ]
      frictionRotation 0.785398 0
      bounce 0
      forceDependentSlip [
        10, 0
      ]
      softCFM 0.0001
    }
  ]
}
Viewpoint {
  orientation -0.10903450729884903 0.8654796139440076 0.4889340590155573 0.9634340988592002
  position -7.8376984770240465 -4.396290626131599 12.572462254955155
}
TexturedBackground {
}
TexturedBackgroundLight {
}
Floor {
}
DEF USER Pedestrian {
  translation 0.76067 -2.37034 1.27
  name "user"
  controller "<none>"
  enableBoundingObject TRUE
}
Solid {
  translation 2.83 -0.08 0.09342156928080458
  children [
    Shape {
      appearance PBRAppearance {
      }
      geometry DEF BALL_GEOMETRY Sphere {
        radius 0.1
      }
    }
  ]
  boundingObject USE BALL_GEOMETRY
  physics Physics {
  }
  linearVelocity 0 0 3.024243306251971e-05
}
DEF DOG Robot {
  translation -0.687690566117882 -0.4894532450682161 0.2752060355275611
  rotation 7.811676178240278e-05 1.5933260963655668e-05 0.9999999968219515 0.5867192308366231
  children [
    DEF ROBOT_BASE Solid {
      translation 0 0 -0.0016935350243008074
      children [
        InertialUnit {
          name "imu"
        }
        Solid {
          translation 0.28 0 -0.00999987
          rotation 0 1 0 -1.5707953071795862
          children [
            Lidar {
              translation 5.87712e-07 0 -0.05
              rotation 0 1 0 1.5708
              name "front_lidar"
            }
            Shape {
              appearance MattePaint {
                baseColor 1 1 0
              }
              geometry Capsule {
                height 0.05
                radius 0.025
              }
            }
          ]
          name "Front_Lidar_Solid"
        }
        Solid {
          translation 0.28 0 0.1
          rotation 0.7071072811865696 -3.3905013482585576e-09 0.7071062811861719 3.14159
          children [
            Shape {
              appearance MattePaint {
                baseColor 0 1 1
              }
              geometry Cylinder {
                height 0.05
                radius 0.02
              }
            }
            Camera {
              translation 2.12131e-07 9.4058e-08 0.025
              rotation -0.707108281185553 -3.3905013482517768e-09 -0.70710528118436 -3.1415853071795863
              name "front_camera"
              fieldOfView 1.52
              width 858
              height 480
              recognition Recognition {
                maxRange 20
                frameColor 0.109804 0.909804 1
                frameThickness 3
                segmentation TRUE
              }
            }
          ]
          name "Front_Camera_Solid"
        }
        Solid {
          translation 0 0 0.15
          children [
            Speaker {
            }
            Shape {
              appearance MattePaint {
                baseColor 0 0.333333 0
              }
              geometry Box {
                size 0.05 0.05 0.05
              }
            }
            GPS {
            }
          ]
          name "GPS"
        }
        HingeJoint {
          jointParameters HingeJointParameters {
            position -16.910186900315367
            axis 0 1 0
            anchor 0.2 -0.2 -0.15
          }
          device [
            RotationalMotor {
              name "front_right_wheel"
            }
            PositionSensor {
            }
          ]
          endPoint Solid {
            translation 0.2 -0.19999999999999996 -0.1499999999999999
            rotation -0.43632095016006534 -0.6362473191938776 0.6362494615086302 3.964430954322679
            children [
              DEF Wheel Shape {
                appearance MattePaint {
                  baseColor 0 0 0
                }
                geometry DEF Wheel_size Cylinder {
                  height 0.05
                  radius 0.125
                }
              }
            ]
            name "wheel_1"
            contactMaterial "InteriorWheelMat"
            boundingObject USE Wheel_size
            physics Physics {
            }
            linearVelocity -0.3579483039786828 -0.2277387340353882 5.459980048659106e-06
            angularVelocity 1.8438730994555832 -2.762114242834866 -0.09934159024758565
          }
        }
        HingeJoint {
          jointParameters HingeJointParameters {
            position 9.390698644986538
            axis 0 1 0
            anchor 0.2 0.2 -0.15
          }
          device [
            RotationalMotor {
              name "front_left_wheel"
            }
            PositionSensor {
            }
          ]
          endPoint Solid {
            translation 0.20000000000000004 0.19999999999999996 -0.15
            rotation -0.012049168946847558 -0.7070542592022822 0.7070566399317681 3.1656897442366048
            children [
              USE Wheel
            ]
            name "wheel_2"
            contactMaterial "ExteriorWheelMat"
            boundingObject USE Wheel_size
            physics Physics {
            }
            linearVelocity -0.3256678514895304 -0.20616567138845107 5.467183109203503e-06
            angularVelocity 1.7504197034698652 -2.622272779448305 -0.09916076226865089
          }
        }
        HingeJoint {
          jointParameters HingeJointParameters {
            position 8.114237253679374
            axis 0 1 0
            anchor -0.2 -0.2 -0.15
          }
          device [
            RotationalMotor {
              name "back_right_wheel"
            }
            PositionSensor {
            }
          ]
          endPoint Solid {
            translation -0.20000000000000004 -0.19999999999999996 -0.15000000000000008
            rotation -0.47749463546624826 -0.6212874832556139 0.6212895751989246 4.032553567693672
            children [
              USE Wheel
            ]
            name "wheel_3"
            contactMaterial "ExteriorWheelMat"
            boundingObject USE Wheel_size
            physics Physics {
            }
            linearVelocity -0.37945824376562953 -0.1954127322580091 -5.464501861507837e-06
            angularVelocity 2.099558014570705 -3.1446133805944894 -0.09983801941503362
          }
        }
        HingeJoint {
          jointParameters HingeJointParameters {
            position -15.629542549067223
            axis 0 1 0
            anchor -0.2 0.2 -0.15
          }
          device [
            RotationalMotor {
              name "back_left_wheel"
            }
            PositionSensor {
            }
          ]
          endPoint Solid {
            translation -0.20000000000000004 0.19999999999999996 -0.15
            rotation 0.02772950796712686 -0.706833682655464 0.7068360626422618 3.08614803231294
            children [
              USE Wheel
            ]
            name "wheel_4"
            contactMaterial "InteriorWheelMat"
            boundingObject USE Wheel_size
            physics Physics {
            }
            linearVelocity -0.34717946562984364 -0.173837067272225 -5.457272365756118e-06
            angularVelocity 1.494817658974265 -2.239693992259136 -0.09870597490003628
          }
        }
        HingeJoint {
          jointParameters HingeJointParameters {
            position 4.656508125
            axis 0 0 1
            anchor -0.12 0 0.2
          }
          device [
            PositionSensor {
            }
            RotationalMotor {
              name "gimbal_j1_motor"
            }
          ]
          endPoint Solid {
            translation -0.12 0 0.2
            rotation -2.346353326862037e-06 -2.2187686638459443e-06 0.9999999999947858 4.656508124994795
            children [
              HingeJoint {
                jointParameters HingeJointParameters {
                  position -0.12500416666666667
                  axis 0 1 0
                  anchor 0 0 0.08
                  minStop -0.52
                  maxStop 0.52
                }
                device [
                  RotationalMotor {
                    name "gimbal_j2_motor"
                  }
                  PositionSensor {
                  }
                ]
                endPoint Solid {
                  translation 0 0 0.08
                  rotation 0.9961061690481515 -0.06233968011719538 0.062339909104047075 1.5747014217232214
                  children [
                    Solid {
                      rotation -0.9999999999999999 0 0 1.5707953071795862
                      children [
                        Camera {
                          translation 0.034 0 0
                          name "RGB_camera"
                          recognitionColors [
                            0 0 0
                          ]
                          fieldOfView 1.518
                          width 640
                          height 480
                          noise 0.01
                          recognition Recognition {
                            segmentation TRUE
                          }
                        }
                        RangeFinder {
                          translation 0.034 0 0
                          name "range_finder"
                          fieldOfView 1.52
                          width 640
                          height 480
                          minRange 0.06
                          maxRange 6
                          noise 0.05
                        }
                        Shape {
                          appearance MattePaint {
                            baseColor 0 0 0
                          }
                          geometry Box {
                            size 0.07 0.18 0.04
                          }
                        }
                      ]
                      name "Depth_Camera"
                    }
                    Shape {
                      appearance MattePaint {
                        baseColor 0 0.666667 1
                      }
                      geometry Cylinder {
                        height 0.2
                        radius 0.03
                      }
                    }
                  ]
                  name "Gimbal_Joint_2"
                }
              }
              Shape {
                appearance MattePaint {
                  baseColor 0.333333 1 1
                }
                geometry Cylinder {
                  height 0.1
                  radius 0.04
                }
              }
            ]
            name "Gimbal_Joint_1"
          }
        }
        Shape {
          appearance MattePaint {
            baseColor 0.333333 0 1
          }
          geometry DEF BASE Box {
            size 0.6 0.3 0.3
          }
        }
      ]
      name "Gimbal"
      boundingObject USE BASE
      physics Physics {
      }
    }
  ]
  physics Physics {
  }
  controller "<extern>"
  supervisor TRUE
  linearVelocity -0.3525688390112708 -0.20079209540350915 7.68924787798536e-10
  angularVelocity 1.82620673799009e-05 -2.7239898431511517e-05 -0.09706697972081293
}
Robot {
  translation 0.1 0 0.1
  name "supervisor1"
  controller "supervisor_controller"
  supervisor TRUE
}
Robot {
  children [
    Solid {
      children [
        Emitter {
        }
        Receiver {
        }
        Shape {
          appearance MattePaint {
            baseColor 0 1 0
          }
          geometry Cone {
            bottomRadius 0.09
            height 0.3
          }
        }
      ]
    }
  ]
  name "remote_server"
}
Atm {
  translation 3 1 0
  rotation 0 0 1 -2.8797953071795863
}
TrashBin {
  translation 0 1.61 0
}
FireHydrant {
  translation 1.75 2.43 0
}
Bench {
  translation 0 -3.34 0
  rotation 2.3464099999897377e-06 1.8004599999921255e-06 0.9999999999956264 1.8326
}
Mailbox {
  translation 2.25 -2.26 0
  rotation 0 0 1 2.87979
}
