#VRML_SIM R2023b utf8

EXTERNPROTO "https://raw.githubusercontent.com/cyberbotics/webots/R2023b/projects/objects/backgrounds/protos/TexturedBackground.proto"
EXTERNPROTO "https://raw.githubusercontent.com/cyberbotics/webots/R2023b/projects/objects/backgrounds/protos/TexturedBackgroundLight.proto"
EXTERNPROTO "https://raw.githubusercontent.com/cyberbotics/webots/R2023b/projects/objects/floors/protos/Floor.proto"
IMPORTABLE EXTERNPROTO "https://raw.githubusercontent.com/cyberbotics/webots/R2023b/projects/humans/pedestrian/protos/Pedestrian.proto"
EXTERNPROTO "https://raw.githubusercontent.com/cyberbotics/webots/R2023b/projects/appearances/protos/MattePaint.proto"

WorldInfo {
  contactProperties [
    ContactProperties {
      material1 "InteriorWheelMat"
      coulombFriction [
        0, 2, 0
      ]
      frictionRotation -0.785398 0
      bounce 0
      forceDependentSlip [
        10, 0
      ]
      softCFM 0.0001
    }
    ContactProperties {
      material1 "ExteriorWheelMat"
      coulombFriction [
        0, 2, 0
      ]
      frictionRotation 0.785398 0
      bounce 0
      forceDependentSlip [
        10, 0
      ]
      softCFM 0.0001
    }
  ]
}
Viewpoint {
  orientation -0.18853922551031177 0.5298032142282371 0.826898733000239 0.8981547484452619
  position -4.1340898332973985 -3.935395013949461 4.043508688277398
}
TexturedBackground {
}
TexturedBackgroundLight {
}
Floor {
}
DEF USER Pedestrian {
  translation 0.76067 -0.850336 1.27
  name "user"
  controller "<none>"
  enableBoundingObject TRUE
}
Solid {
  translation 0.67 0 0.09342527489456763
  children [
    Shape {
      appearance PBRAppearance {
      }
      geometry DEF BALL_GEOMETRY Sphere {
        radius 0.1
      }
    }
  ]
  boundingObject USE BALL_GEOMETRY
  physics Physics {
  }
}
DEF DOG Robot {
  translation 2.11718 1.51331 0.27402
  children [
    DEF ROBOT_BASE Solid {
      translation 0 0 -0.0016935350243008074
      children [
        InertialUnit {
          name "imu"
        }
        Solid {
          translation 0.28 0 -0.00999987
          rotation 0 1 0 -1.5707953071795862
          children [
            Lidar {
              translation 5.87712e-07 0 -0.05
              rotation 0 1 0 1.5708
              name "front_lidar"
            }
            Shape {
              appearance MattePaint {
                baseColor 1 1 0
              }
              geometry Capsule {
                height 0.05
                radius 0.025
              }
            }
          ]
          name "Front_Lidar_Solid"
        }
        Solid {
          translation 0.29 0 0.08
          rotation 0 1 0 -1.5707953071795862
          children [
            Shape {
              appearance MattePaint {
                baseColor 0 1 1
              }
              geometry Cylinder {
                height 0.05
                radius 0.02
              }
            }
            Camera {
              translation 0 0 -0.025
              rotation 0 1 0 1.5708
              name "front_camera"
            }
          ]
          name "Front_Camera_Solid"
        }
        Solid {
          translation 0 0 0.15
          children [
            Speaker {
            }
            Shape {
              appearance MattePaint {
                baseColor 0 0.333333 0
              }
              geometry Box {
                size 0.05 0.05 0.05
              }
            }
            GPS {
            }
          ]
          name "GPS"
        }
        HingeJoint {
          jointParameters HingeJointParameters {
            position -9.998336398374066
            axis 0 1 0
            anchor 0.2 -0.2 -0.15
          }
          device [
            RotationalMotor {
              name "front_right_wheel"
            }
            PositionSensor {
            }
          ]
          endPoint Solid {
            translation 0.20000000000000007 -0.19999999999999996 -0.14999999999999994
            rotation 0.20414081912427604 0.6922150313240171 -0.6922173620882098 2.738846117967549
            children [
              DEF Wheel Shape {
                appearance MattePaint {
                  baseColor 0 0 0
                }
                geometry DEF Wheel_size Cylinder {
                  height 0.05
                  radius 0.125
                }
              }
            ]
            name "wheel_1"
            contactMaterial "InteriorWheelMat"
            boundingObject USE Wheel_size
            physics Physics {
            }
          }
        }
        HingeJoint {
          jointParameters HingeJointParameters {
            position 15.95901205201921
            axis 0 1 0
            anchor 0.2 0.2 -0.15
          }
          device [
            RotationalMotor {
              name "front_left_wheel"
            }
            PositionSensor {
            }
          ]
          endPoint Solid {
            translation 0.20000000000000004 0.19999999999999996 -0.15
            rotation -0.08887533204609034 0.7043074026465661 -0.7043097741270847 3.3188769223454604
            children [
              USE Wheel
            ]
            name "wheel_2"
            contactMaterial "ExteriorWheelMat"
            boundingObject USE Wheel_size
            physics Physics {
            }
          }
        }
        HingeJoint {
          jointParameters HingeJointParameters {
            position 15.96491625001047
            axis 0 1 0
            anchor -0.2 -0.2 -0.15
          }
          device [
            RotationalMotor {
              name "back_right_wheel"
            }
            PositionSensor {
            }
          ]
          endPoint Solid {
            translation -0.2000000000000001 -0.19999999999999996 -0.14999999999999997
            rotation -0.09097113927172074 0.7041735981207191 -0.7041759691506984 3.323034899252182
            children [
              USE Wheel
            ]
            name "wheel_3"
            contactMaterial "ExteriorWheelMat"
            boundingObject USE Wheel_size
            physics Physics {
            }
          }
        }
        HingeJoint {
          jointParameters HingeJointParameters {
            position -10.001474225804698
            axis 0 1 0
            anchor -0.2 0.2 -0.15
          }
          device [
            RotationalMotor {
              name "back_left_wheel"
            }
            PositionSensor {
            }
          ]
          endPoint Solid {
            translation -0.20000000000000004 0.19999999999999996 -0.15000000000000002
            rotation 0.2052722214116438 0.6920477186910434 -0.6920500488918785 2.736674328892199
            children [
              USE Wheel
            ]
            name "wheel_4"
            contactMaterial "InteriorWheelMat"
            boundingObject USE Wheel_size
            physics Physics {
            }
          }
        }
        HingeJoint {
          jointParameters HingeJointParameters {
            axis 0 0 1
            anchor -0.12 0 0.2
          }
          device [
            PositionSensor {
            }
            RotationalMotor {
              name "gimbal_j1_motor"
            }
          ]
          endPoint Solid {
            translation -0.12 0 0.2
            rotation 9.0249935671988e-17 0.9999999999999999 0 4.692706653739929e-06
            children [
              HingeJoint {
                jointParameters HingeJointParameters {
                  axis 0 1 0
                  anchor 0 0 0.08
                  minStop -0.52
                  maxStop 0.52
                }
                device [
                  RotationalMotor {
                    name "gimbal_j2_motor"
                  }
                  PositionSensor {
                  }
                ]
                endPoint Solid {
                  translation 0 0 0.08
                  rotation 1 0 0 1.5707999999999998
                  children [
                    Solid {
                      rotation -0.9999999999999999 0 0 1.5707953071795862
                      children [
                        Camera {
                          translation 0.034 0 0
                          name "RGB_camera"
                          recognitionColors [
                            0 0 0
                          ]
                          fieldOfView 1.518
                          width 640
                          height 480
                          noise 0.01
                          recognition Recognition {
                            segmentation TRUE
                          }
                        }
                        RangeFinder {
                          translation 0.034 0 0
                          name "range_finder"
                          fieldOfView 1.52
                          width 640
                          height 480
                          minRange 0.06
                          maxRange 6
                          noise 0.05
                        }
                        Shape {
                          appearance MattePaint {
                            baseColor 0 0 0
                          }
                          geometry Box {
                            size 0.07 0.18 0.04
                          }
                        }
                      ]
                      name "Depth_Camera"
                    }
                    Shape {
                      appearance MattePaint {
                        baseColor 0 0.666667 1
                      }
                      geometry Cylinder {
                        height 0.2
                        radius 0.03
                      }
                    }
                  ]
                  name "Gimbal_Joint_2"
                }
              }
              Shape {
                appearance MattePaint {
                  baseColor 0.333333 1 1
                }
                geometry Cylinder {
                  height 0.1
                  radius 0.04
                }
              }
            ]
            name "Gimbal_Joint_1"
          }
        }
        Shape {
          appearance MattePaint {
            baseColor 0.333333 0 1
          }
          geometry DEF BASE Box {
            size 0.6 0.3 0.3
          }
        }
      ]
      name "Gimbal"
      boundingObject USE BASE
      physics Physics {
      }
    }
  ]
  physics Physics {
  }
  controller "<extern>"
  supervisor TRUE
}
Robot {
  translation 0.1 0 0.1
  name "supervisor1"
  controller "supervisor_controller"
  supervisor TRUE
}
Robot {
  translation 0 -1.84 0
  name "remote_server"
}
