#VRML_SIM R2023b utf8

EXTERNPROTO "https://raw.githubusercontent.com/cyberbotics/webots/R2023b/projects/objects/backgrounds/protos/TexturedBackground.proto"
EXTERNPROTO "https://raw.githubusercontent.com/cyberbotics/webots/R2023b/projects/objects/backgrounds/protos/TexturedBackgroundLight.proto"
EXTERNPROTO "https://raw.githubusercontent.com/cyberbotics/webots/R2023b/projects/objects/floors/protos/Floor.proto"
IMPORTABLE EXTERNPROTO "https://raw.githubusercontent.com/cyberbotics/webots/R2023b/projects/humans/pedestrian/protos/Pedestrian.proto"
EXTERNPROTO "https://raw.githubusercontent.com/cyberbotics/webots/R2023b/projects/appearances/protos/MattePaint.proto"

WorldInfo {
  contactProperties [
    ContactProperties {
      material1 "InteriorWheelMat"
      coulombFriction [
        0, 2, 0
      ]
      frictionRotation -0.785398 0
      bounce 0
      forceDependentSlip [
        10, 0
      ]
      softCFM 0.0001
    }
    ContactProperties {
      material1 "ExteriorWheelMat"
      coulombFriction [
        0, 2, 0
      ]
      frictionRotation 0.785398 0
      bounce 0
      forceDependentSlip [
        10, 0
      ]
      softCFM 0.0001
    }
  ]
}
Viewpoint {
  orientation -0.12077381448447798 0.34076093932266077 0.9323602672608946 1.6778317208242322
  position 1.1710145563622272 -18.30900675065931 10.359210714227155
}
TexturedBackground {
}
TexturedBackgroundLight {
}
Floor {
}
DEF USER Pedestrian {
  translation 0.76067 -0.850336 1.27
  name "user"
  controller "<none>"
  enableBoundingObject TRUE
}
Solid {
  translation 0.67 0 0.09342527489456763
  children [
    Shape {
      appearance PBRAppearance {
      }
      geometry DEF BALL_GEOMETRY Sphere {
        radius 0.1
      }
    }
  ]
  boundingObject USE BALL_GEOMETRY
  physics Physics {
  }
  linearVelocity 0 0 -2.8769177278730316e-15
}
DEF DOG Robot {
  translation -0.42161973289251026 -0.42162976213727227 0.2752057319446998
  rotation 0.6599891320776856 -0.6964138236224027 0.28181932475784616 0.0018068608581872261
  children [
    DEF ROBOT_BASE Solid {
      translation 0 0 -0.0016935350243008074
      children [
        InertialUnit {
          name "imu"
        }
        Solid {
          translation 0.28 0 -0.00999987
          rotation 0 1 0 -1.5707953071795862
          children [
            Lidar {
              translation 5.87712e-07 0 -0.05
              rotation 0 1 0 1.5708
              name "front_lidar"
            }
            Shape {
              appearance MattePaint {
                baseColor 1 1 0
              }
              geometry Capsule {
                height 0.05
                radius 0.025
              }
            }
          ]
          name "Front_Lidar_Solid"
        }
        Solid {
          translation 0.29 0 0.08
          rotation 0 1 0 -1.5707953071795862
          children [
            Shape {
              appearance MattePaint {
                baseColor 0 1 1
              }
              geometry Cylinder {
                height 0.05
                radius 0.02
              }
            }
            Camera {
              translation 0 0 -0.025
              rotation 0 1 0 1.5708
              name "front_camera"
            }
          ]
          name "Front_Camera_Solid"
        }
        Solid {
          translation 0 0 0.15
          children [
            Speaker {
            }
            Shape {
              appearance MattePaint {
                baseColor 0 0.333333 0
              }
              geometry Box {
                size 0.05 0.05 0.05
              }
            }
            GPS {
            }
          ]
          name "GPS"
        }
        HingeJoint {
          jointParameters HingeJointParameters {
            position -9.998336398374066
            axis 0 1 0
            anchor 0.2 -0.2 -0.15
          }
          device [
            RotationalMotor {
              name "front_right_wheel"
            }
            PositionSensor {
            }
          ]
          endPoint Solid {
            translation 0.20000000000000007 -0.19999999999999996 -0.15
            rotation 0.204140819124293 0.6922150313239396 -0.6922173620882822 2.738846117967638
            children [
              DEF Wheel Shape {
                appearance MattePaint {
                  baseColor 0 0 0
                }
                geometry DEF Wheel_size Cylinder {
                  height 0.05
                  radius 0.125
                }
              }
            ]
            name "wheel_1"
            contactMaterial "InteriorWheelMat"
            boundingObject USE Wheel_size
            physics Physics {
            }
            linearVelocity 0.3545617692131665 0.3548777891174439 -9.596407193063658e-05
            angularVelocity -0.012337011240884018 5.6660970624509694 0.008036674292129283
          }
        }
        HingeJoint {
          jointParameters HingeJointParameters {
            position 15.95901205201921
            axis 0 1 0
            anchor 0.2 0.2 -0.15
          }
          device [
            RotationalMotor {
              name "front_left_wheel"
            }
            PositionSensor {
            }
          ]
          endPoint Solid {
            translation 0.20000000000000007 0.19999999999999996 -0.15000000000000002
            rotation -0.08887533204610086 0.7043074026464787 -0.7043097741271704 3.3188769223454373
            children [
              USE Wheel
            ]
            name "wheel_2"
            contactMaterial "ExteriorWheelMat"
            boundingObject USE Wheel_size
            physics Physics {
            }
            linearVelocity 0.3551482814727589 0.3553814232689447 -0.00321103724340962
            angularVelocity -0.00934679538296801 0.010463247077933582 -0.00020749308555634456
          }
        }
        HingeJoint {
          jointParameters HingeJointParameters {
            position 15.96491625001047
            axis 0 1 0
            anchor -0.2 -0.2 -0.15
          }
          device [
            RotationalMotor {
              name "back_right_wheel"
            }
            PositionSensor {
            }
          ]
          endPoint Solid {
            translation -0.20000000000000007 -0.19999999999999996 -0.15
            rotation -0.09097113927173014 0.7041735981206306 -0.7041759691507855 3.3230348992521543
            children [
              USE Wheel
            ]
            name "wheel_3"
            contactMaterial "ExteriorWheelMat"
            boundingObject USE Wheel_size
            physics Physics {
            }
            linearVelocity 0.3550531517205922 0.35545394269085623 0.0032145313488982138
            angularVelocity -0.00934632554438303 0.009113331324364324 -0.00020951296537081196
          }
        }
        HingeJoint {
          jointParameters HingeJointParameters {
            position -10.001474225804698
            axis 0 1 0
            anchor -0.2 0.2 -0.15
          }
          device [
            RotationalMotor {
              name "back_left_wheel"
            }
            PositionSensor {
            }
          ]
          endPoint Solid {
            translation -0.20000000000000004 0.19999999999999996 -0.15000000000000005
            rotation 0.2052722214116608 0.692047718690964 -0.6920500488919529 2.736674328892282
            children [
              USE Wheel
            ]
            name "wheel_4"
            contactMaterial "InteriorWheelMat"
            boundingObject USE Wheel_size
            physics Physics {
            }
            linearVelocity 0.35464555415825183 0.35496167923096505 9.945634084486107e-05
            angularVelocity -0.012337579299409217 5.667446986726704 0.008038701669411306
          }
        }
        HingeJoint {
          jointParameters HingeJointParameters {
            axis 0 0 1
            anchor -0.12 0 0.2
          }
          device [
            PositionSensor {
            }
            RotationalMotor {
              name "gimbal_j1_motor"
            }
          ]
          endPoint Solid {
            translation -0.12 0 0.2
            rotation 9.024993567198802e-17 1 0 4.692706653739929e-06
            children [
              HingeJoint {
                jointParameters HingeJointParameters {
                  axis 0 1 0
                  anchor 0 0 0.08
                  minStop -0.52
                  maxStop 0.52
                }
                device [
                  RotationalMotor {
                    name "gimbal_j2_motor"
                  }
                  PositionSensor {
                  }
                ]
                endPoint Solid {
                  translation 0 0 0.08
                  rotation 1 0 0 1.5707999999999998
                  children [
                    Solid {
                      rotation 1 0 0 -1.5707953071795862
                      children [
                        Camera {
                          translation -0.036 0 0
                          rotation 0 0 1 3.141592653589793
                          name "RGB_camera"
                          recognitionColors [
                            0 0 0
                          ]
                          fieldOfView 1.518
                          width 640
                          height 480
                          noise 0.01
                          recognition Recognition {
                            segmentation TRUE
                          }
                        }
                        RangeFinder {
                          translation -0.035 0 0
                          rotation 0 0 1 3.141592653589793
                          name "range_finder"
                          fieldOfView 1.52
                          width 640
                          height 480
                          minRange 0.06
                          maxRange 6
                          noise 0.05
                        }
                        Shape {
                          appearance MattePaint {
                            baseColor 0 0 0
                          }
                          geometry Box {
                            size 0.07 0.18 0.04
                          }
                        }
                      ]
                      name "Depth_Camera"
                    }
                    Shape {
                      appearance MattePaint {
                        baseColor 0 0.666667 1
                      }
                      geometry Cylinder {
                        height 0.2
                        radius 0.03
                      }
                    }
                  ]
                  name "Gimbal_Joint_2"
                }
              }
              Shape {
                appearance MattePaint {
                  baseColor 0.333333 1 1
                }
                geometry Cylinder {
                  height 0.1
                  radius 0.04
                }
              }
            ]
            name "Gimbal_Joint_1"
          }
        }
        Shape {
          appearance MattePaint {
            baseColor 0.333333 0 1
          }
          geometry DEF BASE Box {
            size 0.6 0.3 0.3
          }
        }
      ]
      name "Gimbal"
      boundingObject USE BASE
      physics Physics {
      }
    }
  ]
  physics Physics {
  }
  controller "robot_motion_controller"
  supervisor TRUE
  linearVelocity 0.3565524633276485 0.3567827213651697 5.9903713526816435e-06
  angularVelocity -0.009347807082671898 0.009924078056716577 -0.00020828298644490494
}
Robot {
  translation 0.1 0 0.1
  name "supervisor1"
  controller "supervisor_controller"
  supervisor TRUE
}
Robot {
  children [
    Solid {
      children [
        Emitter {
        }
        Receiver {
        }
        Shape {
          appearance MattePaint {
            baseColor 0 1 0
          }
          geometry Cone {
            bottomRadius 0.09
            height 0.3
          }
        }
      ]
    }
  ]
  name "remote_server"
}
